Exception in thread Thread-2 (slow_stream):
Traceback (most recent call last):
  File "/home/marnix/ART/CAMERA/code/gedankenpolizei/.venv/lib/python3.10/site-packages/google/api_core/grpc_helpers.py", line 76, in error_remapped_callable
    return callable_(*args, **kwargs)
  File "/home/marnix/ART/CAMERA/code/gedankenpolizei/.venv/lib/python3.10/site-packages/grpc/_channel.py", line 1181, in __call__
    return _end_unary_response_blocking(state, call, False, None)
  File "/home/marnix/ART/CAMERA/code/gedankenpolizei/.venv/lib/python3.10/site-packages/grpc/_channel.py", line 1006, in _end_unary_response_blocking
    raise _InactiveRpcError(state)  # pytype: disable=not-instantiable
grpc._channel._InactiveRpcError: <_InactiveRpcError of RPC that terminated with:
        status = StatusCode.UNAVAILABLE
        details = "recvmsg:Connection timed out"
        debug_error_string = "UNKNOWN:Error received from peer  {grpc_message:"recvmsg:Connection timed out", grpc_status:14, created_time:"2024-10-03T16:04:00.488300714+02:00"}"
>

The above exception was the direct cause of the following exception:

Traceback (most recent call last):
  File "/usr/lib/python3.10/threading.py", line 1016, in _bootstrap_inner
    self.run()
  File "/usr/lib/python3.10/threading.py", line 953, in run
    self._target(*self._args, **self._kwargs)
  File "/home/marnix/ART/CAMERA/code/gedankenpolizei/src/raw/stream.py", line 104, in slow_stream
    thought = sample_nearby_thought(walk, start, end)
  File "/home/marnix/ART/CAMERA/code/gedankenpolizei/src/slow/thought.py", line 58, in sample_nearby_thought
    step = embed(end) - embed(start)
  File "/home/marnix/ART/CAMERA/code/gedankenpolizei/src/slow/embed.py", line 40, in embed
    embeddings = MODEL.get_embeddings(
  File "/home/marnix/ART/CAMERA/code/gedankenpolizei/.venv/lib/python3.10/site-packages/vertexai/language_models/_language_models.py", line 2187, in get_embeddings
    prediction_response = self._endpoint.predict(
  File "/home/marnix/ART/CAMERA/code/gedankenpolizei/.venv/lib/python3.10/site-packages/google/cloud/aiplatform/models.py", line 1614, in predict
t    prediction_response = self._prediction_client.predict(
  File "/home/marnix/ART/CAMERA/code/gedankenpolizei/.venv/lib/python3.10/site-packages/google/cloud/aiplatform_v1/services/prediction_service/client.py", line 851, in predict
    response = rpc(
  File "/home/marnix/ART/CAMERA/code/gedankenpolizei/.venv/lib/python3.10/site-packages/google/api_core/gapic_v1/method.py", line 131, in __call__
    return wrapped_func(*args, **kwargs)
  File "/home/marnix/ART/CAMERA/code/gedankenpolizei/.venv/lib/python3.10/site-packages/google/api_core/grpc_helpers.py", line 78, in error_remapped_callable
    raise exceptions.from_grpc_error(exc) from exc
google.api_core.exceptions.ServiceUnavailable: 503 recvmsg:Connection timed out